<?xml version="1.0"?>
<robot xmlns:xacro="http://www.ros.org/wiki/xacro">

    <xacro:include filename="colors.xacro" />
    <xacro:include filename="inertial_macros.xacro" />


    <!-- BASE LINK -->

    <link name="base_link">

    </link>


    <!-- BASE_FOOTPRINT LINK -->

    <joint name="base_footprint_joint" type="fixed">
        <parent link="base_link" />
        <child link="base_footprint" />
        <origin xyz="0 0 0" rpy="0 0 0" />
    </joint>

    <link name="base_footprint">
    </link>


    <!-- CHASSIS LINK -->

    <joint name="chassis_joint" type="fixed">
        <parent link="base_link" />
        <child link="chassis" />
        <origin xyz="-0.41 0 0" />
    </joint>

    <link name="chassis">
        <visual>
            <origin xyz="0.41 0 0.115" />
            <geometry>
                <box size="0.82 0.65 0.23" />
            </geometry>
            <material name="orange" />
        </visual>
        <collision>
            <origin xyz="0.41 0 0.115" />
            <geometry>
                <box size="0.82 0.65 0.23" />
            </geometry>
        </collision>
        <xacro:inertial_box mass="0.5" x="0.3" y="0.3" z="0.15">
            <origin xyz="0.15 0 0.075" rpy="0 0 0" />
        </xacro:inertial_box>
    </link>

    <gazebo reference="chassis">
        <material>Gazebo/Orange</material>
    </gazebo>

    <!-- LEFT WHEEL LINK -->

    <joint name="left_wheel_joint" type="continuous">
        <parent link="base_link" />
        <child link="left_wheel" />
        <origin xyz="0 0.303 -0.075" rpy="-${pi/2} 0 0" />
        <axis xyz="0 0 1" />
    </joint>

    <link name="left_wheel">
        <visual>
            <geometry>
                <cylinder radius="0.075" length="0.045" />
            </geometry>
            <material name="blue" />
        </visual>
        <collision>
            <geometry>
                <sphere radius="0.075" />
            </geometry>
        </collision>
        <xacro:inertial_cylinder mass="0.1" length="0.045" radius="0.075">
            <origin xyz="0 0 0" rpy="0 0 0" />
        </xacro:inertial_cylinder>
    </link>

    <gazebo reference="left_wheel">
        <material>Gazebo/Blue</material>
    </gazebo>

    <!-- RIGHT WHEEL LINK -->

    <joint name="right_wheel_joint" type="continuous">
        <parent link="base_link" />
        <child link="right_wheel" />
        <origin xyz="0 -0.303 -0.075" rpy="${pi/2} 0 0" />
        <axis xyz="0 0 -1" />
    </joint>

    <link name="right_wheel">
        <visual>
            <geometry>
                <cylinder radius="0.075" length="0.045" />
            </geometry>
            <material name="blue" />
        </visual>
        <collision>
            <geometry>
                <sphere radius="0.075" />
            </geometry>
        </collision>
        <xacro:inertial_cylinder mass="0.1" length="0.045" radius="0.075">
            <origin xyz="0 0 0" rpy="0 0 0" />
        </xacro:inertial_cylinder>
    </link>

    <gazebo reference="right_wheel">
        <material>Gazebo/Blue</material>
    </gazebo>

    <!-- CASTER WHEEL LINK FRONT LEFT-->

    <joint name="caster_wheel_joint_FL" type="fixed">
        <parent link="chassis" />
        <child link="caster_wheel_fl" />
        <origin xyz="0.745 0.325 -0.075" rpy="-${pi/2} 0 0" />
    </joint>


    <link name="caster_wheel_fl">
        <visual>
            <geometry>
                <cylinder radius="0.075" length="0.045" />
            </geometry>
            <material name="black" />
        </visual>
        <collision>
            <geometry>
                <sphere radius="0.075" />
            </geometry>
        </collision>
        <xacro:inertial_cylinder mass="0.1" length="0.045" radius="0.075">
            <origin xyz="0 0 0" rpy="0 0 0" />
        </xacro:inertial_cylinder>
    </link>

    <gazebo reference="caster_wheel_fl">
        <material>Gazebo/Black</material>
        <mu1 value="0.001" />
        <mu2 value="0.001" />
    </gazebo>


    <!-- CASTER WHEEL LINK FRONT RIGHT-->

    <joint name="caster_wheel_joint_FR" type="fixed">
        <parent link="chassis" />
        <child link="caster_wheel_fr" />
        <origin xyz="0.745 -0.325 -0.075" rpy="${pi/2} 0 0" />
    </joint>


    <link name="caster_wheel_fr">
        <visual>
            <geometry>
                <cylinder radius="0.075" length="0.045" />
            </geometry>
            <material name="black" />
        </visual>
        <collision>
            <geometry>
                <sphere radius="0.075" />
            </geometry>
        </collision>
        <xacro:inertial_cylinder mass="0.1" length="0.045" radius="0.075">
            <origin xyz="0 0 0" rpy="0 0 0" />
        </xacro:inertial_cylinder>
    </link>

    <gazebo reference="caster_wheel_fr">
        <material>Gazebo/Black</material>
        <mu1 value="0.001" />
        <mu2 value="0.001" />
    </gazebo>


    <!-- CASTER WHEEL LINK REAR RIGHT-->

    <joint name="caster_wheel_joint_RR" type="fixed">
        <parent link="chassis" />
        <child link="caster_wheel_rr" />
        <origin xyz="0.075 -0.325 -0.075" rpy="${pi/2} 0 0" />
    </joint>


    <link name="caster_wheel_rr">
        <visual>
            <geometry>
                <cylinder radius="0.075" length="0.045" />
            </geometry>
            <material name="black" />
        </visual>
        <collision>
            <geometry>
                <sphere radius="0.075" />
            </geometry>
        </collision>
        <xacro:inertial_cylinder mass="0.1" length="0.045" radius="0.075">
            <origin xyz="0 0 0" rpy="0 0 0" />
        </xacro:inertial_cylinder>
    </link>

    <gazebo reference="caster_wheel_rr">
        <material>Gazebo/Black</material>
        <mu1 value="0.001" />
        <mu2 value="0.001" />
    </gazebo>


    <!-- CASTER WHEEL LINK REAR LEFT-->

    <joint name="caster_wheel_joint_RL" type="fixed">
        <parent link="chassis" />
        <child link="caster_wheel_rl" />
        <origin xyz="0.075 0.325 -0.075" rpy="-${pi/2} 0 0" />
    </joint>


    <link name="caster_wheel_rl">
        <visual>
            <geometry>
                <cylinder radius="0.075" length="0.045" />
            </geometry>
            <material name="black" />
        </visual>
        <collision>
            <geometry>
                <sphere radius="0.075" />
            </geometry>
        </collision>
        <xacro:inertial_cylinder mass="0.1" length="0.045" radius="0.075">
            <origin xyz="0 0 0" rpy="0 0 0" />
        </xacro:inertial_cylinder>
    </link>

    <gazebo reference="caster_wheel_rl">
        <material>Gazebo/Black</material>
        <mu1 value="0.001" />
        <mu2 value="0.001" />
    </gazebo>


</robot>